2020-12-21 15:24:55,798 DEBUG (MadisServer::post) QueryExecutionException: &2 0 -1 1216970 0 0 0
!(mapi:monetdb://monetdb@88.197.53.136/voc10) Table: missing 'sys.localuser2351089_1'
!25005!Current transaction is aborted (please ROLLBACK)

2020-12-21 15:24:55,799 INFO 200 POST / (127.0.0.1) 95.96ms
2020-12-21 15:24:55,799 ERROR Uncaught exception POST / (127.0.0.1)
HTTPServerRequest(protocol='http', host='127.0.0.1:7779', method='POST', uri='/', version='HTTP/1.1', remote_ip='127.0.0.1')
Traceback (most recent call last):
  File "/home/openaire/.local/lib/python3.7/site-packages/tornado/web.py", line 1703, in _execute
    result = await result
  File "mserver.py", line 52, in post
    result = await run_algorithm.run(algorithm, params, db_objects)
  File "/home/openaire/exareme2_runtime/monetdb_federated_poc/global/run_algorithm.py", line 38, in run
    result = await scheduler_instance.schedule()
  File "/home/openaire/exareme2_runtime/monetdb_federated_poc/global/scheduler.py", line 52, in schedule
    result = await self.run_global(self.step, task['run_global'])
  File "/home/openaire/exareme2_runtime/monetdb_federated_poc/global/scheduler.py", line 118, in run_global
    result = await self.task_executor.task_global(step, self.global_schema, step_global['sqlscript'])
  File "/home/openaire/exareme2_runtime/monetdb_federated_poc/global/task_executor.py", line 146, in task_global
    result = await cur.execute(query)
  File "/home/openaire/exareme2_runtime/monetdb_federated_poc/global/aiopymonetdb/sql/cursors.py", line 174, in execute
    block = await self.connection.execute(query)
  File "/home/openaire/exareme2_runtime/monetdb_federated_poc/global/aiopymonetdb/sql/connections.py", line 277, in execute
    return await self.command("s" + query + "\n;")
  File "/home/openaire/exareme2_runtime/monetdb_federated_poc/global/aiopymonetdb/sql/connections.py", line 282, in command
    return await self.mapi.cmd(command)
  File "/home/openaire/exareme2_runtime/monetdb_federated_poc/global/aiopymonetdb/mapi_async.py", line 297, in cmd
    raise exception('\n'.join(lines))
pymonetdb.exceptions.OperationalError: &2 0 -1 1216970 0 0 0
!(mapi:monetdb://monetdb@88.197.53.136/voc10) Table: missing 'sys.localuser2351089_1'
!25005!Current transaction is aborted (please ROLLBACK)

